Traceback (most recent call last):
  File "/Users/mp/opt/anaconda3/lib/python3.9/site-packages/jupyter_cache/executors/utils.py", line 51, in single_nb_execution
    executenb(
  File "/Users/mp/opt/anaconda3/lib/python3.9/site-packages/nbclient/client.py", line 1112, in execute
    return NotebookClient(nb=nb, resources=resources, km=km, **kwargs).execute()
  File "/Users/mp/opt/anaconda3/lib/python3.9/site-packages/nbclient/util.py", line 74, in wrapped
    return just_run(coro(*args, **kwargs))
  File "/Users/mp/opt/anaconda3/lib/python3.9/site-packages/nbclient/util.py", line 53, in just_run
    return loop.run_until_complete(coro)
  File "/Users/mp/opt/anaconda3/lib/python3.9/asyncio/base_events.py", line 642, in run_until_complete
    return future.result()
  File "/Users/mp/opt/anaconda3/lib/python3.9/site-packages/nbclient/client.py", line 553, in async_execute
    await self.async_execute_cell(
  File "/Users/mp/opt/anaconda3/lib/python3.9/site-packages/nbclient/client.py", line 857, in async_execute_cell
    self._check_raise_for_error(cell, exec_reply)
  File "/Users/mp/opt/anaconda3/lib/python3.9/site-packages/nbclient/client.py", line 760, in _check_raise_for_error
    raise CellExecutionError.from_cell_and_msg(cell, exec_reply_content)
nbclient.exceptions.CellExecutionError: An error occurred while executing the following cell:
------------------
#@title 


def normal_dist(mu=170, sigma=20):
  plt.figure(figsize=(10, 6))
  x = np.linspace(mu - 10*sigma, mu + 10*sigma, 1000)
  plt.axvline(mu, color='r', linestyle='--')
  plt.plot(x, stats.norm.pdf(x, mu, sigma), label='Distribution de la population')
  plt.title('Distribution de la taille dans la population', fontsize=20)
  plt.ylabel('Densit√©', fontsize=20)
  plt.xlabel('Taille (cm)', fontsize=20)
  plt.xlim(100, 250)
  plt.tick_params(labelsize=15)

interactive_plot = interact_manual(normal_dist, mu=(100,240),sigma=(1,40))
output = interactive_plot.children[-1]


------------------

[0;31m---------------------------------------------------------------------------[0m
[0;31mAttributeError[0m                            Traceback (most recent call last)
[0;32m/var/folders/wh/nq4sjhnx3634k2wbw7tc977w0000gn/T/ipykernel_21757/1604337990.py[0m in [0;36m<module>[0;34m[0m
[1;32m     14[0m [0;34m[0m[0m
[1;32m     15[0m [0minteractive_plot[0m [0;34m=[0m [0minteract_manual[0m[0;34m([0m[0mnormal_dist[0m[0;34m,[0m [0mmu[0m[0;34m=[0m[0;34m([0m[0;36m100[0m[0;34m,[0m[0;36m240[0m[0;34m)[0m[0;34m,[0m[0msigma[0m[0;34m=[0m[0;34m([0m[0;36m1[0m[0;34m,[0m[0;36m40[0m[0;34m)[0m[0;34m)[0m[0;34m[0m[0;34m[0m[0m
[0;32m---> 16[0;31m [0moutput[0m [0;34m=[0m [0minteractive_plot[0m[0;34m.[0m[0mchildren[0m[0;34m[[0m[0;34m-[0m[0;36m1[0m[0;34m][0m[0;34m[0m[0;34m[0m[0m
[0m[1;32m     17[0m [0;34m[0m[0m

[0;31mAttributeError[0m: 'function' object has no attribute 'children'
AttributeError: 'function' object has no attribute 'children'

